Interação IA - Concorrência

Pergunta: O que acontece se um Future falhar e como posso lidar com esse erro?

Quando um **Future** falha em Dart, isso significa que ele completou com um erro em vez de um valor válido. Isso pode acontecer, por exemplo, quando uma operação assíncrona lança uma exceção, como uma requisição HTTP que retorna erro, uma leitura de arquivo que falha, etc.

### O que acontece quando um Future falha?

* O **Future** é completado com erro.
* Qualquer código que aguarde esse Future usando `await` receberá uma exceção.
* Qualquer código que use `.then()` não entrará no callback do `.then()`, mas sim no callback do `.catchError()` (se houver).

### Como lidar com erros em Future?

Existem duas formas comuns:

---

### 1. Usando `try-catch` com `await`

```dart
Future<void> fetchData() async {
  try {
    var data = await someAsyncFunction();
    print('Dados recebidos: $data');
  } catch (e) {
    print('Erro ao buscar dados: $e');
  }
}
```

* Aqui, o erro lançado pelo Future será capturado no `catch`.

---

### 2. Usando `.then()` e `.catchError()`

```dart
someAsyncFunction()
  .then((data) {
    print('Dados recebidos: $data');
  })
  .catchError((error) {
    print('Erro ao buscar dados: $error');
  });
```

* O callback dentro do `.catchError()` será chamado se o Future falhar.

---

### Observação importante:

* Se você não tratar o erro (não usar `try-catch` ou `catchError`), o erro será lançado para cima e pode causar a finalização do programa ou ser capturado por um handler global (em Flutter, por exemplo, pode mostrar um erro na tela).

---

Quer que eu te mostre um exemplo completo de tratamento de erro com Future, ou talvez exemplos específicos de algum cenário (HTTP, leitura de arquivo)?

//Observações: Estava na dúvida do que aconteceria caso acontecesse um erro nessa situação de esperar um valor por meio do Future, porque não havia visto ninguém falando dessa possibilidade, porém eu consegui entender todo esse tratamento feito caso haja um erro por meio da explicação da IA.

Pergunta: Como posso simular um erro em um Future usando Future.error?

Simular um erro em um **Future** usando `Future.error` é bem simples e útil para testar como seu código lida com falhas assíncronas.

### Como usar `Future.error`

`Future.error` cria um Future que completa imediatamente com um erro.

```dart
Future<String> simulateError() {
  return Future.error('Simulação de erro');
}
```

---

### Exemplo completo com tratamento

```dart
void main() async {
  try {
    var result = await Future.error('Erro simulado');
    print('Resultado: $result'); // Isso não será executado
  } catch (e) {
    print('Erro capturado: $e');  // Aqui o erro será tratado
  }
}
```

---

### Usando com `.then()` e `.catchError()`

```dart
Future.error('Erro simulado')
  .then((value) => print('Resultado: $value'))  // Nunca será chamado
  .catchError((error) => print('Erro capturado: $error'));
```

---

### Para quê usar `Future.error`?

* Testar o fluxo de tratamento de erros.
* Simular falhas em operações assíncronas.
* Garantir que seu código lide corretamente com exceções.

Se quiser, posso montar um exemplo mais elaborado para você! Quer?

//Observações: Acho bem interessante essa parte de simular erros quando se está testando um código, e como o Future é uma funcionalidade totalmente nova para mim, achei interessante ter uma noção de como poderia forçar os erros no Future para testar o código por meio do Future.error.